Workbook
Name status: #REF!

Sheet Quantitativo de PI
A1: Instituto Federal de Alagoas - IFAL Pró-Reitoria de Pesquisa, Pós-Graduação e Inovação - PRPPI Diretoria de Pesquisa e Inovação Coordenação do Núcleo de Inovação Tecnológica
A7: Controle Geral de Titularidades e Cotitularidades de PI (Atualizado em Abril de 2026)
A9: PI | B9: AÇÃO | C9: 2015 | D9: 2016 | E9: 2017 | F9: 2018 | G9: 2019 | H9: 2020 | I9: 2021 | J9: 2022 | K9: 2023 | L9: 2024 | M9: 2025 | N9: 2026 | O9: TOTAL
A10: PATENTE | B10: DEPÓSITO | C10: - | D10: - | E10: - | F10: - | G10: =COUNTA('2019'!B4:B16) -> 4 | H10: =COUNTA('2020'!B4:B16) -> 1 | I10: =COUNTA('2021'!B4:B13) -> 6 | J10: =COUNTA('2022'!B4:B15) -> 7 | K10: =COUNTA('2023'!B4:B16) -> 8 | L10: =COUNTA('2024'!B4:B16) -> 3 | M10: =COUNTA('2025'!B4:B16) -> 5 | N10: =COUNTA('2026'!B5:B18) -> 14 | O10: =SUM(C10:N10) -> 48
B11: CONCESSÕES | C11: - | D11: - | E11: - | F11: - | G11: - | H11: - | I11: - | J11: - | K11: - | L11: - | M11: - | N11: - | O11: =SUM(C11:N11) -> 0
A12: PROGRAMA DE COMPUTADOR | B12: DEPÓSITO | C12: =COUNTA('2015'!B19:B31) -> 2 | D12: =COUNTA('2016'!B19:B31) -> 3 | E12: - | F12: - | G12: =COUNTA('2019'!B19:B35) -> 17 | H12: =COUNTA('2020'!B19:B31) -> 8 | I12: =COUNTA('2021'!B16:B28) -> 12 | J12: =COUNTA('2022'!B18:B35) -> 18 | K12: =COUNTA('2023'!B19:B31) -> 13 | L12: =COUNTA('2024'!B19:B31) -> 8 | M12: =COUNTA('2025'!B19:B31) -> 12 | N12: =COUNTA('2026'!B23:B34) -> 8 | O12: =SUM(C12:N12) -> 101
B13: CONCESSÕES | C13: =COUNTIF('2015'!G19:G31,C9) -> 2 | D13: =COUNTIF('2016'!G19:G31,D9) -> 3 | E13: - | F13: - | G13: =COUNTIF('2019'!G19:G35,G9) -> 17 | H13: =COUNTIF('2020'!G19:G31,H9) -> 8 | I13: =COUNTIF('2021'!G16:G28,I9) -> 12 | J13: =COUNTIF('2022'!G18:G35,J9) -> 18 | K13: =COUNTIF('2023'!G19:G31,K9) -> 13 | L13: =COUNTIF('2024'!G19:G31,L9) -> 8 | M13: =COUNTIF('2025'!G19:G31,M9) -> 12 | N13: =COUNTIF('2026'!G23:G34,N9) -> 8 | O13: =SUM(C13:N13) -> 101
A14: DESENHO INDUSTRIAL | B14: DEPÓSITO | C14: - | D14: - | E14: - | F14: - | G14: =COUNTA('2019'!B38:B50) -> 11 | H14: - | I14: - | J14: - | K14: - | L14: - | M14: - | N14: - | O14: =SUM(C14:N14) -> 11
B15: CONCESSÕES | C15: - | D15: - | E15: - | F15: - | G15: =COUNTIF('2019'!G38:G50,G9) -> 11 | H15: - | I15: - | J15: - | K15: - | L15: - | M15: - | N15: - | O15: =SUM(C15:N15) -> 11
A19: Patentes depositadas + Registros de Desenho Industrial concedidos + Registros de Programa de Computador concedidos | C19: =O10+O15+O13 -> 160
A23: QUANTITATIVO DE PI´s POR CAMPI
A24: CAMPI | B24: CATEGORIA | C24: DEPÓSITO / CONCESSÃO | D24: TOTAL
A25: MACEIÓ | B25: PATENTE | C25: =COUNTIF('2015'!D4:D16,A25)+COUNTIF('2016'!D4:D16,A25)+COUNTIF('2017'!D4:D16,A25)+COUNTIF('2018'!D4:D16,A25)+COUNTIF('2019'!D4:D16,A25)+COUNTIF('2020'!D4:D16,A25)+COUNTIF('2021'!D4:D13,A25)+COUNTIF('2022'!D4:D15,A25)+COUNTIF('2023'!D4:D16,A25)+COUNTIF('2024'!D4:D16,A25)+COUNTIF('2025'!D4:D16,A25)+COUNTIF('2026'!D5:D20,A25) -> 15 | D25: =C25+C26+C27 -> 71 | E25: Cotitularidade | F25: TOTAL | G25: =G26+G27+G28 -> 160
B26: PROGRAMA DE COMPUTADOR | C26: =COUNTIF('2015'!D19:D31,A25)+COUNTIF('2016'!D19:D31,A25)+COUNTIF('2017'!D19:D31,A25)+COUNTIF('2018'!D19:D31,A25)+COUNTIF('2019'!D19:D35,A25)+COUNTIF('2020'!D19:D31,A25)+COUNTIF('2021'!D16:D28,A25)+COUNTIF('2022'!D18:D35,A25)+COUNTIF('2023'!D19:D31,A25)+COUNTIF('2024'!D19:D31,A25)+COUNTIF('2025'!D19:D31,A25)+COUNTIF('2026'!D23:D34,A25) -> 45 | E26: 5 | F26: PATENTE | G26: =C25+C28+C31+C34+C37+C40+C43+C46+C49+C52+C55+C58+C61+C64+C67+C70+C73 -> 48
B27: DESENHO INDUSTRIAL | C27: =COUNTIF('2019'!D38:D50,A25)+COUNTIF('2025'!D34:D46,A25)+COUNTIF('2026'!D37:D49,A25) -> 11 | E27: 12 | F27: SOFTWARE | G27: =C26+C29+C32+C35+C38+C41+C44+C47+C50+C53+C56+C59+C62+C65+C68+C71+C74 -> 101
A28: ARAPIRACA | B28: PATENTE | C28: =COUNTIF('2015'!D4:D16,A28)+COUNTIF('2016'!D4:D16,A28)+COUNTIF('2017'!D4:D16,A28)+COUNTIF('2018'!D4:D16,A28)+COUNTIF('2019'!D4:D16,A28)+COUNTIF('2020'!D4:D16,A28)+COUNTIF('2021'!D4:D13,A28)+COUNTIF('2022'!D4:D15,A28)+COUNTIF('2023'!D4:D16,A28)+COUNTIF('2024'!D4:D16,A28)+COUNTIF('2025'!D4:D16,A28)+COUNTIF('2026'!D5:D18,A28) -> 0 | D28: =C28+C29+C30 -> 16 | E28: 0 | F28: DESENHO | G28: =C27+C30+C33+C36+C39+C42+C45+C48+C51+C54+C57+C60+C63+C66+C69+C72+C75 -> 11
B29: PROGRAMA DE COMPUTADOR | C29: =COUNTIF('2015'!D19:D31,A28)+COUNTIF('2016'!D19:D31,A28)+COUNTIF('2017'!D19:D31,A28)+COUNTIF('2018'!D19:D31,A28)+COUNTIF('2019'!D19:D35,A28)+COUNTIF('2020'!D19:D31,A28)+COUNTIF('2021'!D16:D28,A28)+COUNTIF('2022'!D18:D35,A28)+COUNTIF('2023'!D19:D31,A28)+COUNTIF('2024'!D19:D31,A28)+COUNTIF('2025'!D19:D31,A28)+COUNTIF('2026'!D23:D34,A28) -> 16 | E29: Total = 17
B30: DESENHO INDUSTRIAL | C30: =COUNTIF('2019'!D38:D50,A28)+COUNTIF('2025'!D34:D46,A28)+COUNTIF('2026'!D37:D49,A28) -> 0
A31: SATUBA | B31: PATENTE | C31: =COUNTIF('2015'!D4:D16,A31)+COUNTIF('2016'!D4:D16,A31)+COUNTIF('2017'!D4:D16,A31)+COUNTIF('2018'!D4:D16,A31)+COUNTIF('2019'!D4:D16,A31)+COUNTIF('2020'!D4:D16,A31)+COUNTIF('2021'!D4:D13,A31)+COUNTIF('2022'!D4:D15,A31)+COUNTIF('2023'!D4:D16,A31)+COUNTIF('2024'!D4:D16,A31)+COUNTIF('2025'!D4:D16,A31)+COUNTIF('2026'!D5:D18,A31) -> 2 | D31: =C31+C32+C33 -> 3
B32: PROGRAMA DE COMPUTADOR | C32: =COUNTIF('2015'!D19:D31,A31)+COUNTIF('2016'!D19:D31,A31)+COUNTIF('2017'!D19:D31,A31)+COUNTIF('2018'!D19:D31,A31)+COUNTIF('2019'!D19:D35,A31)+COUNTIF('2020'!D19:D31,A31)+COUNTIF('2021'!D16:D28,A31)+COUNTIF('2022'!D18:D35,A31)+COUNTIF('2023'!D19:D31,A31)+COUNTIF('2024'!D19:D31,A31)+COUNTIF('2025'!D19:D31,A31)+COUNTIF('2026'!D23:D34,A31) -> 1
B33: DESENHO INDUSTRIAL | C33: =COUNTIF('2019'!D38:D50,A31)+COUNTIF('2025'!D34:D46,A31)+COUNTIF('2026'!D37:D49,A31) -> 0
A34: MARECHAL DEODORO | B34: PATENTE | C34: =COUNTIF('2015'!D4:D16,A34)+COUNTIF('2016'!D4:D16,A34)+COUNTIF('2017'!D4:D16,A34)+COUNTIF('2018'!D4:D16,A34)+COUNTIF('2019'!D4:D16,A34)+COUNTIF('2020'!D4:D16,A34)+COUNTIF('2021'!D4:D13,A34)+COUNTIF('2022'!D4:D15,A34)+COUNTIF('2023'!D4:D16,A34)+COUNTIF('2024'!D4:D16,A34)+COUNTIF('2025'!D4:D16,A34)+COUNTIF('2026'!D5:D18,A34) -> 7 | D34: =C34+C35+C36 -> 16
B35: PROGRAMA DE COMPUTADOR | C35: =COUNTIF('2015'!D19:D31,A34)+COUNTIF('2016'!D19:D31,A34)+COUNTIF('2017'!D19:D31,A34)+COUNTIF('2018'!D19:D31,A34)+COUNTIF('2019'!D19:D35,A34)+COUNTIF('2020'!D19:D31,A34)+COUNTIF('2021'!D16:D28,A34)+COUNTIF('2022'!D18:D35,A34)+COUNTIF('2023'!D19:D31,A34)+COUNTIF('2024'!D19:D31,A34)+COUNTIF('2025'!D19:D31,A34)+COUNTIF('2026'!D23:D34,A34) -> 9
B36: DESENHO INDUSTRIAL | C36: =COUNTIF('2019'!D38:D50,A34)+COUNTIF('2025'!D34:D46,A34)+COUNTIF('2026'!D37:D49,A34) -> 0
A37: SÃO MIGUEL DOS CAMPUS | B37: PATENTE | C37: =COUNTIF('2015'!D4:D16,A37)+COUNTIF('2016'!D4:D16,A37)+COUNTIF('2017'!D4:D16,A37)+COUNTIF('2018'!D4:D16,A37)+COUNTIF('2019'!D4:D16,A37)+COUNTIF('2020'!D4:D16,A37)+COUNTIF('2021'!D4:D13,A37)+COUNTIF('2022'!D4:D15,A37)+COUNTIF('2023'!D4:D16,A37)+COUNTIF('2024'!D4:D16,A37)+COUNTIF('2025'!D4:D16,A37)+COUNTIF('2026'!D5:D18,A37) -> 0 | D37: =C37+C38+C39 -> 0
B38: PROGRAMA DE COMPUTADOR | C38: =COUNTIF('2015'!D19:D31,A37)+COUNTIF('2016'!D19:D31,A37)+COUNTIF('2017'!D19:D31,A37)+COUNTIF('2018'!D19:D31,A37)+COUNTIF('2019'!D19:D35,A37)+COUNTIF('2020'!D19:D31,A37)+COUNTIF('2021'!D16:D28,A37)+COUNTIF('2022'!D18:D35,A37)+COUNTIF('2023'!D19:D31,A37)+COUNTIF('2024'!D19:D31,A37)+COUNTIF('2025'!D19:D31,A37)+COUNTIF('2026'!D23:D34,A37) -> 0
B39: DESENHO INDUSTRIAL | C39: =COUNTIF('2019'!D38:D50,A37)+COUNTIF('2025'!D34:D46,A37)+COUNTIF('2026'!D37:D49,A37) -> 0
A40: PALMEIRA DOS ÍNDIOS | B40: PATENTE | C40: =COUNTIF('2015'!D4:D16,A40)+COUNTIF('2016'!D4:D16,A40)+COUNTIF('2017'!D4:D16,A40)+COUNTIF('2018'!D4:D16,A40)+COUNTIF('2019'!D4:D16,A40)+COUNTIF('2020'!D4:D16,A40)+COUNTIF('2021'!D4:D13,A40)+COUNTIF('2022'!D4:D15,A40)+COUNTIF('2023'!D4:D16,A40)+COUNTIF('2024'!D4:D16,A40)+COUNTIF('2025'!D4:D16,A40)+COUNTIF('2026'!D5:D18,A40) -> 2 | D40: =C40+C41+C42 -> 7
B41: PROGRAMA DE COMPUTADOR | C41: =COUNTIF('2015'!D19:D31,A40)+COUNTIF('2016'!D19:D31,A40)+COUNTIF('2017'!D19:D31,A40)+COUNTIF('2018'!D19:D31,A40)+COUNTIF('2019'!D19:D35,A40)+COUNTIF('2020'!D19:D31,A40)+COUNTIF('2021'!D16:D28,A40)+COUNTIF('2022'!D18:D35,A40)+COUNTIF('2023'!D19:D31,A40)+COUNTIF('2024'!D19:D31,A40)+COUNTIF('2025'!D19:D31,A40)+COUNTIF('2026'!D23:D34,A40) -> 5
B42: DESENHO INDUSTRIAL | C42: =COUNTIF('2019'!D38:D50,A40)+COUNTIF('2025'!D34:D46,A40)+COUNTIF('2026'!D37:D49,A40) -> 0
A43: CORURIPE | B43: PATENTE | C43: =COUNTIF('2015'!D4:D16,A43)+COUNTIF('2016'!D4:D16,A43)+COUNTIF('2017'!D4:D16,A43)+COUNTIF('2018'!D4:D16,A43)+COUNTIF('2019'!D4:D16,A43)+COUNTIF('2020'!D4:D16,A43)+COUNTIF('2021'!D4:D13,A43)+COUNTIF('2022'!D4:D15,A43)+COUNTIF('2023'!D4:D16,A43)+COUNTIF('2024'!D4:D16,A43)+COUNTIF('2025'!D4:D16,A43)+COUNTIF('2026'!D5:D18,A43) -> 2 | D43: =C43+C44+C45 -> 2
B44: PROGRAMA DE COMPUTADOR | C44: =COUNTIF('2015'!D19:D31,A43)+COUNTIF('2016'!D19:D31,A43)+COUNTIF('2017'!D19:D31,A43)+COUNTIF('2018'!D19:D31,A43)+COUNTIF('2019'!D19:D35,A43)+COUNTIF('2020'!D19:D31,A43)+COUNTIF('2021'!D16:D28,A43)+COUNTIF('2022'!D18:D35,A43)+COUNTIF('2023'!D19:D31,A43)+COUNTIF('2024'!D19:D31,A43)+COUNTIF('2025'!D19:D31,A43)+COUNTIF('2026'!D23:D34,A43) -> 0
B45: DESENHO INDUSTRIAL | C45: =COUNTIF('2019'!D38:D50,A43)+COUNTIF('2025'!D34:D46,A43)+COUNTIF('2026'!D37:D49,A43) -> 0
A46: MURICI | B46: PATENTE | C46: =COUNTIF('2015'!D4:D16,A46)+COUNTIF('2016'!D4:D16,A46)+COUNTIF('2017'!D4:D16,A46)+COUNTIF('2018'!D4:D16,A46)+COUNTIF('2019'!D4:D16,A46)+COUNTIF('2020'!D4:D16,A46)+COUNTIF('2021'!D4:D13,A46)+COUNTIF('2022'!D4:D15,A46)+COUNTIF('2023'!D4:D16,A46)+COUNTIF('2024'!D4:D16,A46)+COUNTIF('2025'!D4:D16,A46)+COUNTIF('2026'!D5:D18,A46) -> 5 | D46: =C46+C47+C48 -> 5
B47: PROGRAMA DE COMPUTADOR | C47: =COUNTIF('2015'!D19:D31,A46)+COUNTIF('2016'!D19:D31,A46)+COUNTIF('2017'!D19:D31,A46)+COUNTIF('2018'!D19:D31,A46)+COUNTIF('2019'!D19:D35,A46)+COUNTIF('2020'!D19:D31,A46)+COUNTIF('2021'!D16:D28,A46)+COUNTIF('2022'!D18:D35,A46)+COUNTIF('2023'!D19:D31,A46)+COUNTIF('2024'!D19:D31,A46)+COUNTIF('2025'!D19:D31,A46)+COUNTIF('2026'!D23:D34,A46) -> 0
B48: DESENHO INDUSTRIAL | C48: =COUNTIF('2019'!D38:D50,A46)+COUNTIF('2025'!D34:D46,A46)+COUNTIF('2026'!D37:D49,A46) -> 0
A49: PENEDO | B49: PATENTE | C49: =COUNTIF('2015'!D4:D16,A49)+COUNTIF('2016'!D4:D16,A49)+COUNTIF('2017'!D4:D16,A49)+COUNTIF('2018'!D4:D16,A49)+COUNTIF('2019'!D4:D16,A49)+COUNTIF('2020'!D4:D16,A49)+COUNTIF('2021'!D4:D13,A49)+COUNTIF('2022'!D4:D15,A49)+COUNTIF('2023'!D4:D16,A49)+COUNTIF('2024'!D4:D16,A49)+COUNTIF('2025'!D4:D16,A49)+COUNTIF('2026'!D5:D18,A49) -> 6 | D49: =C49+C50+C51 -> 10
B50: PROGRAMA DE COMPUTADOR | C50: =COUNTIF('2015'!D19:D31,A49)+COUNTIF('2016'!D19:D31,A49)+COUNTIF('2017'!D19:D31,A49)+COUNTIF('2018'!D19:D31,A49)+COUNTIF('2019'!D19:D35,A49)+COUNTIF('2020'!D19:D31,A49)+COUNTIF('2021'!D16:D28,A49)+COUNTIF('2022'!D18:D35,A49)+COUNTIF('2023'!D19:D31,A49)+COUNTIF('2024'!D19:D31,A49)+COUNTIF('2025'!D19:D31,A49)+COUNTIF('2026'!D23:D34,A49) -> 4
B51: DESENHO INDUSTRIAL | C51: =COUNTIF('2019'!D38:D50,A49)+COUNTIF('2025'!D34:D46,A49)+COUNTIF('2026'!D37:D49,A49) -> 0
A52: SANTANA DO IPANEMA | B52: PATENTE | C52: =COUNTIF('2015'!D4:D16,A52)+COUNTIF('2016'!D4:D16,A52)+COUNTIF('2017'!D4:D16,A52)+COUNTIF('2018'!D4:D16,A52)+COUNTIF('2019'!D4:D16,A52)+COUNTIF('2020'!D4:D16,A52)+COUNTIF('2021'!D4:D13,A52)+COUNTIF('2022'!D4:D15,A52)+COUNTIF('2023'!D4:D16,A52)+COUNTIF('2024'!D4:D16,A52)+COUNTIF('2025'!D4:D16,A52)+COUNTIF('2026'!D5:D18,A52) -> 0 | D52: =C52+C53+C54 -> 0
...

Sheet 2026
A1: Solicitações — 2026
A2: Pedidos de Patentes
A3: Nº | B3: Projeto | C3: Orientador | D3: Campus | E3: E-mail | F3: Status | G3: Ano de concessão | H3: Processo INPI | I3: Processo no Sipac
A4: 1 | B4: Argamassa de assentamento com substituição parcial do agregado miúdo por biomassa de Egeria densa | C4: Ronny Francisco Marques de Souza; Eliédson Rafael de Carvalho; Johnnatan Duarte de Freitas; Maria Simone Correia da Silva; Eduardo Victor Santos Da Silva; Brenno Ferreira Cavalcante, | D4: Piranhas | E4: johnnatan.duarte@ifal.edu.br | F4: Acompanhamento na revista | G4: 2026 | H4: BR 10 2026 008184 1 | I4: 23041.021472/2024-09
A5: 2 | B5: Utilização do pó de casca de sururu na revelação de impressões digitais latentes | C5: Ashley Sabrina Lopes Santos; Jéssica Higino de Souza; Maria Eduarda Ramos Malaquias; Rosanny Christhinny da Silva; Fred Augusto Ribeiro Nogueira | D5: Maceió | E5: fred.nogueira@ifal.edu.br | F5: Acompanhamento na revista | G5: 2026 | H5: BR 10 2026 000801 0 | I5: 23041.037452/2025-22
A6: 3 | B6: Bioplástico inteligente de caroço de abacate e antocianina da casca da uva | C6: Beatriz Nascimento Ribeiro; Maria Sabrina Amaro da Silva; João Gabriel Gomes Otacílio; Vívia Heloísa Brito de Souza; Vívia Heloísa Brito de Souza; Antônia Angelica Correia de Araújo; Natalia Miranda do Nascimento; Nataly Miranda do Nascimento | D6: Murici | E6: nataly.nascimento@ifal.edu.br | F6: Acompanhamento na revista | G6: 2026 | H6: BR 10 2026 001316 1 | I6: 23041.038738/2025-25
A7: 4 | B7: Bioplástico de amido de semente de jaca e própolis vermelha de Alagoas para conservação de alimentos | C7: Rebeca Ferreira da Silva; Letícia Vicente da Silva; Eduardo Jorge da Silva Fonseca; Geovana Dresch Weble; Nataly Miranda do Nascimento | D7: Murici | E7: nataly.nascimento@ifal.edu.br | F7: Acompanhamento na revista | G7: 2026 | H7: BR 10 2026 001353 6 | I7: 23041.045399/2025-33
A8: 5 | B8: Metodologia otimizada para a extração e especiação de cromo em sedimentos superficiais através do uso do bloco digestor | C8: Elisangela Costa Santos; Juci Alana Santos Silva; Maria Witórya Silva dos Santos | D8: Penedo | E8: elisangela.santos@ifal.edu.br | F8: Acompanhamento na revista | G8: 2026 | H8: BR 10 2026 000498 7 | I8: 23041.039248/2025-46
A9: 6 | B9: Caracterização orgânica do mel | C9: Doriedson Silva Santos Junior; David Antônio Menezes dos Santos; Elisangela Costa Santos | D9: Penedo | E9: elisangela.santos@ifal.edu.br | F9: Acompanhamento na revista | G9: 2026 | H9: BR 10 2026 000619 0 | I9: 23041.046607/2025-11
A10: 7 | B10: Extração de fósforo em sedimentos superficiais por meio de bloco digestor | C10: Juci Alana Santos Silva; Doriedson Silva Santos Junior; Elisangela Costa Santos | D10: Penedo | E10: elisangela.santos@ifal.edu.br | F10: Acompanhamento na revista | G10: 2026 | H10: BR 10 2026 002260 8 | I10: 23041.046861/2025-10
A11: 8 | B11: Sistema à base de resíduos de manga para adsorção e liberação de misturas de semioquímicos. | C11: Johnnatan D. De Freitas | D11: Maceió | E11: johnnatan.duarte@ifal.edu.br | F11: Acompanhamento na revista | G11: 2026 | H11: BR 10 2026 005156 0 | I11: 23041.050715/2025-99
A12: 9 | B12: Análise de material compósito para reparação e tratamento de fendas em madeira de eucalipto reflorestado em Alagoas. | C12: Aurea Luiza Quixabeira | D12: Maceió | E12: aurea.raposo@ifal.edu.br | F12: Acompanhamento na revista | G12: 2026 | H12: BR 10 2026 006795 4 | I12: 23041.002524/2026-00
A13: 10 | B13: Processo Sustentável e Econômico para Redução de Óxido de Grafeno Usando Ferro Metálico | C13: Adonias França | D13: Piranhas | E13: jose.franca@ifal.edu.br | F13: Acompanhamento na revista | G13: 2026 | H13: BR 10 2026 012084 7 | I13: 23041.049205/2025-79
A14: 11 | B14: Sistema de isolamento composto de RECIPIENTE TÉRMICO BICOMPOSITO DE ENDOCARPO DE COCOS NICIFERA. | C14: Eduardo Henrique Viana de Sousa | D14: Maceió | E14: eduardo.sousa@ifal.edu.br | F14: Acompanhamento na revista | G14: 2026 | H14: BR 10 2026 012071 5 | I14: 23041.015122/2025-86
A15: 12 | B15: MoniToRH% Monitor de Umidade e Temperatura sem contato para pastas cerâmicas | C15: Marcelo Assis Correa | D15: Maceió | E15: marcelo.assis@ifal.edu.br | F15: Acompanhamento na revista | G15: 2026 | H15: BR 10 2026 010989 4 | I15: SomosCOTitular
... A18: 15 | B18: Sistema de Liberação de Semioquímicos à Base de Manta Eletrofiada de Policaprolactona com Carvão Ativado Incorporado e Processo de Obtenção | C18: Clara Andrezza Crisóstomo Bezerra Costa, Ligia Maria Manzine Costa, Alan John Duarte de Freitas, Henrique Fonseca Goulart (Ufal), Antonio Euzébio Goulart de Sant'ana (Ufal) e Johnnatan Duarte de Freitas. | D18: Maceió | E18: johnnatan.duarte@ifal.edu.br | F18: Acompanhamento na revista | G18: 2026 | H18: BR 10 2026 014111 9 | I18: 23041.016513/2026-07
A19: 16
A20: 17
A21: Registros de programa de computador
A22: Nº | B22: Projeto | C22: Orientador | D22: Campus | E22: E-mail | F22: Status | G22: Ano de concessão | H22: Processo INPI | I22: Processo no Sipac
A23: 1 | B23: Nonextensive statistics in the one-dimensional parity-conserving particle process with Levy branching and no diffusion | C23: Ana Tereza Santana Mendes; Carlos Argolo Pereira Alves; | D23: Maceió | E23: cleber.nauber@ifal.edu.br | F23: Registro concedido | G23: 2026 | H23: BR 51 2026 000619 8 | I23: 23041.049192/2025-38
A24: 2 | B24: EGRESSOS | C24: Cleber Nauber dos Santos; Macelo Leite Lyra | D24: Maceió | E24: cleber.nauber@ifal.edu.br | F24: Registro concedido | G24: 2026 | H24: BR 51 2026 000622 8 | I24: 23041.049337/2025-09
A25: 3 | B25: PLATAFORMA DOKYE | C25: Mônica Ximenes Carneiro da Cunha | D25: Maceió | E25: monica@ifal.edu.br | F25: Registro concedido | G25: 2026 | H25: BR 51 2026 000016 5 | I25: 23041.039239/2025-55
A26: 4 | B26: Teatalk | C26: Mônica Ximenes Carneiro da Cunha | D26: Maceió | E26: monica@ifal.edu.br | F26: Registro concedido | G26: 2026 | H26: BR 51 2026 002078 6 | I26: 23041.006870/2026-59
A27: 5 | B27: OportunEdu | C27: Fernando Kenji Kamei | D27: Maceió | E27: fernando.kenji@ifal.edu.br | F27: Registro concedido | G27: 2026 | H27: BR 51 2026 003223 7 | I27: 23041.038795/2025-12
A28: 6 | B28: IFCARE - Pronto Atendimento Acadêmico Integrado | C28: Fernanda Calheiros Peixoto | D28: Maceió | E28: fernanda.calheiros@ifal.edu.br | F28: Registro concedido | G28: 2026 | H28: BR 51 2026 003007 2 | I28: 23041.002228/2026-09
A29: 7 | B29: LETRAMUNDO | C29: Mônica Ximenes Carneiro da Cunha | D29: Maceió | E29: monica@ifal.edu.br | F29: Registro concedido | G29: 2026 | H29: BR 51 2026 004803 6 | I29: 23041.014545/2026-60 - 23041.017187/2026-47 proc de pg
A30: 8 | B30: TEAGRAM | C30: Mônica Ximenes Carneiro da Cunha | D30: Maceió | E30: monica@ifal.edu.br | F30: Registro concedido | G30: 2026 | H30: BR 51 2026 005588 1 | I30: 23041.014564/2026-96 - 23041.017192/2026-50 proc de pg
A31: 9
A32: 10
A33: 11
A34: 12
A35: Registros de desenho industrial
A36: Nº | B36: Projeto | C36: Orientador | D36: Campus | E36: E-mail | F36: Status | G36: Ano de concessão | H36: Processo INPI | I36: Processo no Sipac
A37: 1
A38: 2
A39: 3
A40: 4
A41: 5
A42: 6
...

Sheet 2025
A1: Solicitações — 2025
A2: Pedidos de Patentes
A3: Nº | B3: Projeto | C3: Orientador | D3: Campus | E3: E-mail | F3: Status | G3: Ano de concessão | H3: Processo INPI | I3: Processo no Sipac
A4: 1 | B4: Balas de goma utilizando produtos apícolas | C4: PROFª DENISE | D4: Piranhas | E4: denise.araujo@ifal,edu.br | F4: Acompanhamento na revista | G4: 2025 | H4: BR 10 2025 028911 3 | I4: 23041.045597/2025-05
A5: 2 | B5: Aproveitamento de pó de vidro proveniente de garrafas pós-consumo para produção de ladrilho hidráulico piso tátil | C5: SHEILA KAROLINE | D5: Marechal Deodoro | E5: sheyla.marques@ifal.edu.br | F5: Acompanhamento na revista | G5: 2025 | H5: BR 10 2025 027083 8 | I5: 23041.027409/2025-59
A6: 3 | B6: Tijolo Sustentável ( Feito De Plástico Reciclado Para Utilização Na Construção Civil) | C6: ELISANGELA SANTOS | D6: Penedo | E6: elisangela.santos@ifal.edu.br | F6: Acompanhamento na revista | G6: 2025 | H6: BR 10 2025 016309 8 | I6: 23041.027058/2025-86
A7: 4 | B7: Somos COTitular | C7: — | D7: Marechal Deodoro | E7: — | F7: Acompanhamento na revista | G7: 2025 | H7: BR 10 2025 017759 5 | I7: SomosCOTitular
A8: 5 | B8: Argamassa De Assentamento Com Substituição Parcial Do Agregado Miúdo Por Conchas Trituradas De Limnoperna fortunei | C8: Ronny Francisco Marques de Souza; Sheyla Karolina Justino Marques; Dara Liandra Lira Pinto; Dara Liandra Lira Pinto; Fabrícia Moreira da Silva | D8: Piranhas | E8: sheyla.marques@ifal.edu.br | F8: Acompanhamento na revista | G8: 2025 | H8: BR 10 2025 016308 0 | I8: 23041.032856/2024-49
A9: 6
A10: 7
A11: 8
A12: 9
A13: 10
A14: 11
A15: 12
A16: 13
A17: Registros de programa de computador
A18: Nº | B18: Projeto | C18: Orientador | D18: Campus | E18: E-mail | F18: Status | G18: Ano de concessão | H18: Processo INPI | I18: Processo no Sipac
A19: 1 | B19: Random Food | C19: Emylle Chrystinne da Silva Euzébio; Arthur Passos de Melo; Jardel Cleyson da Silva; Flávio Mota Medeiros | D19: Maceió | E19: jardelcleyson@gmail.com | F19: Registro concedido | G19: 2025 | H19: BR 51 2025 000985 2 | I19: 23041.041753/2024-70
A20: 2 | B20: ALEX - Uma plataforma virtual para educação híbrida inclusiva e centrada no estudante | C20: Breno Jacinto Duarte da Costa; Márcio Martins; Fábio Paraguaçu; João Victor Berta | D20: Maceió | E20: brenojac@ifal.edu.br | F20: Registro concedido | G20: 2025 | H20: BR 51 2025 000165 7 | I20: 23041.043611/2024-47
A21: 3 | B21: Critical dynamics of epidemic processes with Lévy-like diffusion | C21: Cleber Nauber dos Santos; Carlos Argolo Pereira Alves; Marcelo Leite Lyra | D21: Maceió | E21: cleber.nauber@ifal.edu.br | F21: Registro concedido | G21: 2025 | H21: BR 51 2025 002134 8 | I21: 23041.013808/2025-32
A22: 4 | B22: Dinâmica de espalhamento critico de caminhantes aleatórios aniquilantes conservando a paridade com ramificação em lei de potência. | C22: Cleber Nauber dos Santos; Carlos Argolo Pereira Alves; Marcelo Leite Lyra | D22: Maceió | E22: cleber.nauber@ifal.edu.br | F22: Registro concedido | G22: 2025 | H22: BR 51 2025 001682 4 | I22: 23041.039486/2024-71
A23: 5 | B23: Rotina Divertida com Hugo e Sofia | C23: Katiúcia Wanessa Ramos da Silva; Jonata Santos Ramalho; Mônica Ximenes Carneiro da Cunha | D23: Maceió | E23: monica@ifal.edu.br | F23: Registro concedido | G23: 2025 | H23: BR 51 2025 002829 6 | I23: 23041.022955/2025-01
A24: 6 | B24: SIMEC- Sistema Integrado de Mecânica Educacional Conectada | C24: Eduardo Henrique Viana de Sousa / Rebeca Tirza Medeiros Frazão | D24: Maceió | E24: eduardo.sousa@ifal.edu.br. | F24: Registro concedido | G24: 2025 | H24: BR 51 2025 002982 9 | I24: 23041.022705/2025-63
A25: 7 | B25: GreenGrow | C25: Davi Carnaúba de Lima Vieira; Fernando Kenji Kamei; Gabriel Afonso Lins de Melo; Mikhael de Oliveira Silva D'Amato; Francisco Rafael da Silva Pereira | D25: Satuba | E25: fernando.kenji@ifal.edu.br | F25: Registro concedido | G25: 2025 | H25: BR 51 2025 003510 1 | I25: 23041.023228/2025-53
A26: 8 | B26: GizmoObjects | C26: Eyder Tinoco Ferreira Neto; Fernando Kenji Kamei; Gabriel Afonso Lins de Melo; Mikhael de Oliveira Silva D'amato | D26: Maceió | E26: fernando.kenji@ifal.edu.br | F26: Registro concedido | G26: 2025 | H26: BR 51 2025 004358 9 | I26: 23041.022244/2025-29
A27: 9 | B27: SIMPLIFICA | C27: Guilherme de Jesus Vieira; Marcos Vinicius França Silva; Maurício Vieira Dias Júnior; Ruan Ranison da Costa Silva | D27: Arapiraca | E27: mauricio.dias@ifal.edu.br | F27: Registro concedido | G27: 2025 | H27: BR 51 2025 004485 2 | I27: 23041.047272/2024-78
A28: 10 | B28: GizmoCode | C28: Mônica Ximenes Carneiro da Cunha; Gabriel Afonso Lins de Melo; Mikhael de Oliveira Silva D'amato; Eyder Tinoco Ferreira Neto | D28: Maceió | E28: monica@ifal.edu.br | F28: Registro concedido | G28: 2025 | H28: BR 51 2025 006057 2 | I28: 23041.040238/2025-53
A29: 11 | B29: Chatbot Acadêmico IFAL.IA | C29: Luiz Felipe Naziazeno Neto; Ronny Francisco Marques De Souza; Cinthia Régia Dos Santos Freitas | D29: Piranhas | E29: ronny.souza@ifal.edu.br | F29: Registro concedido | G29: 2025 | H29: BR 51 2025 006184 6 | I29: 23041.046198/2025-53
A30: 12 | B30: Software para análise de temperatura e umidade utilizando ESP32, MySQL, PHP | C30: Luiz Felipe Naziazeno Neto; Cristian José Simões Costa; Cinthia Régia dos Santos Freitas; Aristófanes Matias Gomes da Silva; Vitoria Rodrigues Vieira; Kawã Ailton Monteiro Lima; Davi Henrique Soares Ferreira; Robson Júnior Gonçalves Fernandes; João Ernesto Pereira Mota | D30: Piranhas | E30: luiz.felipe@ifal.edu.br | F30: Registro concedido | G30: 2025 | H30: BR 51 2025 000753 1 | I30: 23041.001462/2025-20
A31: 13
A32: Registros de desenho industrial
A33: Nº | B33: Projeto | C33: Orientador | D33: Campus | E33: E-mail | F33: Status | G33: Ano de concessão | H33: Processo INPI | I33: Processo no Sipac
A34: 1
A35: 2
A36: 3
A37: 4
A38: 5
A39: 6
A40: 7
...

Sheet 2024
A1: Solicitações — 2024
A2: Pedidos de Patentes
A3: Nº | B3: Projeto | C3: Orientador | D3: Campus | E3: E-mail | F3: Status | G3: Ano de concessão | H3: Processo INPI | I3: Processo no Sipac
A4: 1 | B4: Potenciostato para Análises Eletroquímicas | C4: Rodrigues Lima; Francisco de Assis dos Santos Silva; Cleylton Bezerra Lopes | D4: Maceió | E4: charles.lucena@ifal.edu.br | F4: Acompanhamento na revista | G4: 2024 | H4: BR 10 2024 001900 8 | I4: 23041.043564/2023-51
A5: 2 | B5: Iogurte batido sabor manga reduzido de açúcar e enriquecido com açafrão | C5: Silvania Alves Ladeira; Juliano Silva Lima; Adriel Silva Barros; Ana Carolina Rodrigues de Araújo; Mario Jirlanio Guilherme Santos; Roberta Barbosa Teodoro Alves | D5: Piranhas | E5: roberta.alves@ifal.edu.br | F5: Acompanhamento na revista | G5: 2024 | H5: BR 10 2024 023293 3 | I5: 23041.030851/2024-81
A6: 3 | B6: Análise das Características e Propriedades do Plástico Reforçado com Fibra de Vidro e Lodo de Estação de Tratamento de Água na Produção de Cerâmicas Porosas | C6: Sheyla Karolina Justino Marques | D6: Marechal Deodoro | E6: sheyla.marques@ifal.edu.br | F6: Acompanhamento na revista | G6: 2024 | H6: BR 10 2024 023286 0 | I6: 23041.023593/2024-87
A7: 4
A8: 5
A9: 6
A10: 7
A11: 8
A12: 9
A13: 10
A14: 11
A15: 12
A16: 13
A17: Registros de programa de computador
A18: Nº | B18: Projeto | C18: Orientador | D18: Campus | E18: E-mail | F18: Status | G18: Ano de concessão | H18: Processo INPI | I18: Processo no Sipac
A19: 1 | B19: Alfa Beto e jogos de linguagem (PROCESSO 23041.051091/2023-65 PAGAMENTO DE GUIA DE RECOLHIMENTO DA UNIÃO - GRU) | C19: Ana Luiza Azevedo Fireman; Luiz Felipe Naziazeno Neto; Luiz Filipe Barbosa Varjão | D19: Piranhas | E19: luiz.felipe@ifal.edu.br | F19: Registro concedido | G19: 2024 | H19: BR 51 2024 000130 1 | I19: 23041.051033/2023-31
A20: 2 | B20: Voucher Digital | C20: Alexandre Paes Dos Santos, Davi Goncalves Valerio, Douglas Afonso Tenorio De Menezes, Manuel Eduardo Nascimento Antunes | D20: Arapiraca | E20: mena1@aluno.ifal.edu.br | F20: Registro concedido | G20: 2024 | H20: BR 51 2024 002028 4 | I20: 23041.014371/2024-73
A21: 3 | B21: Modelo de análise de ervas daninhas utilizando inteligência artificial com auxílio de imagens de satélite | C21: Luiz Felipe Naziazeno Neto; Luiz Filipe Barbosa Varjão; Ronny Francisco Marques De Souza; Yan Felipe Pereira Fernandes; Jarbas José De Souza Silva | D21: Piranhas | E21: luiz.felipe@ifal.edu.br | F21: Registro concedido | G21: 2024 | H21: BR 51 2024 002605 3 | I21: 23041.018538/2024-75
A22: 4 | B22: ECOPONTO | C22: Wallisson Rony de Magalhães Neves; Tarsis Marinho de Souza; Andesson Mendes de Freitas; Augusto César Lúcio de Oliveira; Renato Alves Timoteo Muniz; Ana Catarina Monteiro Carvalho Mori da Cunha; Emerson Floriano da Silva; Ruan Ranison da Costa Silva | D22: Arapiraca | E22: tarsis.souza@ifal.edu.br | F22: Registro concedido | G22: 2024 | H22: BR 51 2024 002604 5 | I22: 23041.020755/2024-25
A23: 5 | B23: SEJA - Sistema de Estágios e Jovem Aprendiz | C23: Lucas Gabriel Peixoto De Oliveira; Lucilene Da Silva Bezerra; Dilliani Felipe Barros De Oliveira; Leonardo Fernandes Mendonça De Oliveira | D23: Reitoria | E23: dilliani.oliveira@ifal.edu.br | F23: Registro concedido | G23: 2024 | H23: BR 51 2024 002606 1 | I23: 23041.018462/2024-88
A24: 6 | B24: SouTec Backend | C24: Alan Pedro Da Silva; Alisson Werner Arruda De Arruda; Diego Dermeval Medeiros Da Cunha Matos; Helena Macedo Reis; Ibsen Mateus Bittencourt Santana Pinto; Ig Ibert Bittencourt Santana Pinto; Ivo Augusto Andrade Rocha Calado; Joedna Lobato Do Amaral Hubner; Seiji Isotani; Sofia De Almeida Prado Simanke; Thiago Araújo Silva De Oliveira | D24: Maceió | E24: alan.pedro@ifal.edu.br | F24: Registro concedido | G24: 2024 | H24: BR 51 2024 000191 3 | I24: Somos COTitular
A25: 7 | B25: SouTec Crawler | C25: Alan Pedro Da Silva; Alisson Werner Arruda De Arruda; Diego Dermeval Medeiros Da Cunha Matos; Helena Macedo Reis; Ibsen Mateus Bittencourt Santana Pinto; Ig Ibert Bittencourt Santana Pinto; Ivo Augusto Andrade Rocha Calado; Joedna Lobato Do Amaral Hubner; Seiji Isotani; Sofia De Almeida Prado Simanke; Thiago Araújo Silva De Oliveira | D25: Maceió | E25: alan.pedro@ifal.edu.br | F25: Registro concedido | G25: 2024 | H25: BR 51 2024 000151 4 | I25: Somos COTitular
A26: 8 | B26: SouTec aplicação móvel | C26: Alan Pedro Da Silva; Alisson Werner Arruda De Arruda; Diego Dermeval Medeiros Da Cunha Matos; Helena Macedo Reis; Ibsen Mateus Bittencourt Santana Pinto; Ig Ibert Bittencourt Santana Pinto; Ivo Augusto Andrade Rocha Calado; Joedna Lobato Do Amaral Hubner; Seiji Isotani; Sofia De Almeida Prado Simanke; Thiago Araújo Silva De Oliveira | D26: Maceió | E26: alan.pedro@ifal.edu.br | F26: Registro concedido | G26: 2024 | H26: BR 51 2024 000185 9 | I26: Somos COTitular
A27: 9
A28: 10
A29: 11
A30: 12
A31: 13
A32: Registros de desenho industrial
A33: Nº | B33: Projeto | C33: Orientador | D33: Campus | E33: E-mail | F33: Status | G33: Ano de concessão | H33: Processo INPI | I33: Processo no Sipac
A34: 1
A35: 2
A36: 3
A37: 4
A38: 5
A39: 6
A40: 7
...

Sheet 2023
A1: Solicitações — 2023
A2: Pedidos de Patentes
A3: Nº | B3: Projeto | C3: Orientador | D3: Campus | E3: E-mail | F3: Status | G3: Ano de concessão | H3: Processo INPI | I3: Processo no Sipac
A4: 1 | B4: Processo De Sintese E Caracterização De Microesferas Carregadas Com Rincoforol Comaplicação Em Dispensadores De Feromônios | C4: Alan John Duarte de Freitas; Johnnatan Duarte Freitas; Jennifer Mclaine Duarte de Freitas; Demetrius Pereira Morilla; Clara Andrezza Crisóstomo Bezerra Costa; Luis Carlos Ferreira de Oliveira; Orlando Francisco da Silva Moura; Mikael De Lima Freitas; Celso Silva Caldas; Ingrid Sofia Vieira de Melo; Jório Bezerra Cabral Júnior; Fabrício Daniel dos Santos Silva; João Gomes da Costa; Jessé Marques da Silva Júnior Pavão; José Robério Cavalcante Da Silva; Fabiane Caxico de Abreu Galdino; Ticiano Gomes do Nascimento; Ruth Rufino do Nascimento | D4: Maceió | E4: johnnatan.duarte@ifal.edu.br | F4: Acompanhamento na revista | G4: 2023 | H4: BR 10 2023 026116 7 | I4: 23041.007216/2023-10
A5: 2 | B5: Avaliação da Viabilidade Técnica, Econômica e Ambiental da Produção de Piso Intertravado com Agregado da Concha de Sururu | C5: Arthur Amaral Batista Tenório; Sheyla Karolina Justino Marques | D5: Marechal Deodoro | E5: sheyla.marques@ifal.edu.br | F5: Acompanhamento na revista | G5: 2023 | H5: BR 10 2023 026115 9 | I5: 23041.044128/2023-07
A6: 3 | B6: Processo de obtenção de compósito obtido através dos sacos de cimentos de papel kraft após otimização com hidróxido de sódio (NaOH) | C6: Ricardo Calheiros Soares; Luciano Oliveira Alves de Queiros | D6: Palmeira dos Índios | E6: ricardo.soares@ifal.edu.br | F6: Acompanhamento na revista | G6: 2023 | H6: BR 10 2023 015076 4 | I6: 23041.025090/2023-65
A7: 4 | B7: Purificador de Água Inteligente e Personalizável com Monitoramento Individualizado e Integração com Comércio Eletrônico (Purificador Health Care) | C7: Davi Carnaúba de Lima Vieira | D7: Satuba | E7: davi.carnauba@ifal.edu.br | F7: Acompanhamento na revista | G7: 2023 | H7: BR 10 2023 018732 3 | I7: 23041.030497/2023-12
A8: 5 | B8: Fabricação de concreto com incorporação de fibras de papel kraft provenientes de embalagens de cimento pós-uso recicladas | C8: Eliédon Rafael de Carvalho; Shyla Karolina Justino Marques | D8: Palmeira dos Índios | E8: sheyla.marques@ifal.edu.br | F8: Acompanhamento na revista | G8: 2023 | H8: BR 10 2023 005097 2 | I8: 23041.004879/2023-82
A9: 6 | B9: Peneira rotativa de baixo custo, com reaproveitamento de materiais, para separar o sururu de sua casca | C9: Allisson Luiz Nascimento da Silva; Juliane Cabral Silva; Paulo dos Santos Silva; Sheldon Cristiano Souza da Silva; Kamilly Nascimento dos Santos; João Gustavo de Oliveira Souza; Vitória Beatriz Herculano Lopes; Livia Karolynne Vieira de luna; Bianca Letícia Ferreira dos Santos; Jacksiel José de Abreu; Alberto Jorge Santos de Almeida; José Henrick Viana Ramalho; Rômulo Afonso Luna Vianna de Omena; | D9: Maceió | E9: allisson.silva@ifal.edu.br | F9: Acompanhamento na revista | G9: 2023 | H9: BR 10 2023 008818 0 | I9: 23041.003347/2023-28
A10: 7 | B10: Compostagem de resíduos agroindústrias de polpa de frutas para uso na produção de mudas | C10: Alessandra Cristina de Lima Soares; André Suêldo Tavares de Lima; Erika Socorro Alves Graciano de Vasconcelos; Mateus Emanuel de Mendonça Alves; Tays Myrelle de Vasconcelos Siqueira | D10: Murici | E10: alessandracdelimasoares@gmail.com | F10: Acompanhamento na revista | G10: 2023 | H10: BR 10 2023 000939 5 | I10: 23041.054129/2022-71
A11: 8 | B11: Robô de emissão de radiação ultravioleta. | C11: Jacksiel José de Abreu; Allisson Luiz Nascimento da Silva; José Henrick Viana Ramalho; Alberto Jorge Santos de Almeida; Rômulo Afonso Luna Vianna de Omena | D11: Maceió | E11: jacksiel.abreu@ifal.edu.br | F11: Acompanhamento na revista | G11: 2023 | H11: BR 10 2023 008626 8 | I11: 23041.052339/2022-24
A12: 9
A13: 10
A14: 11
A15: 12
A16: 13
A17: Registros de programa de computador
A18: Nº | B18: Projeto | C18: Orientador | D18: Campus | E18: E-mail | F18: Status | G18: Ano de concessão | H18: Processo INPI | I18: Processo no Sipac
A19: 1 | B19: INCLUSAO GAME | C19: Eduardo Cardoso Moraes; Victor Phellyppe S. De Oliveira | D19: Maceió | E19: eduardo.moraes@ifal.edu.br | F19: Registro concedido | G19: 2023 | H19: BR 51 2023 001174 6 | I19: 23041.005097/2022-80
A20: 2 | B20: Random Laser Montecarlo simulation in fortran | C20: Andre Lima Moura; Carlos Argolo Pereira Alves; Cleber Nauber Dos Santos; Samuel Silva Albuquerque | D20: Maceió | F20: Registro concedido | G20: 2023 | H20: BR 51 2023 001137 1 | I20: 23041.003632/2023-49
A21: 3 | B21: QuiLibras | C21: Elisangela Costa Santos; Ermesson Lima Dos Santos; Everson Vinicius Soares Do Nascimento | D21: Penedo | F21: Registro concedido | G21: 2023 | H21: BR 51 2023 001579 2 | I21: 23041.014569/2023-76
A22: 4 | B22: Plataforma Ciberfísica para Irrigação Inteligente (PC2I) | C22: Daniel Lacet De Faria Fireman; Felipe Alencar Lops | D22: Arapiraca | F22: Registro concedido | G22: 2023 | H22: BR 51 2023 001814 7 | I22: 23041.021741/2023-48
A23: 5 | B23: Processo epidêmico difusivo 2d | C23: Carlos Argolo Pereira Alves; Cleber Nauber Dos Santos; Iram Marcelo Gléria; Marcelo Leite Lyra; Miguel Barrios Luis Nauber | D23: Maceió | F23: Registro concedido | G23: 2023 | H23: BR 51 2023 001581 4 | I23: 23041.017250/2023-01
A24: 6 | B24: Processo epidêmico difusivo 2d dinâmico | C24: Carlos Argolo Pereira Alves; Cleber Nauber Dos Santos; Iram Marcelo Gléria; Marcelo Leite Lyra; Miguel Barrios Luis Nauber | D24: Maceió | F24: Registro concedido | G24: 2023 | H24: BR 51 2023 001815 5 | I24: 23041.022337/2023-91
A25: 7 | B25: CCG - Centro de Cruzamento Genético | C25: Ebenézer Bernardes Correia Silva; Jedson Emanoel Da Silva Zu; Maria Luzenita Wagner Mallmann; Nathan Rafael Mendonça De Assis; Sara Nicoly Ferreira Lins | D25: Maceió | F25: Registro concedido | G25: 2023 | H25: BR 51 2023 002214 4 | I25: 23041.025957/2023-82
A26: 8 | B26: PD&S ANALYTICS | C26: Cleber Nauber Dos Santos; Edison Camilo De Moraes Jr; Marcelo Embiruçu De Souza; Marcio Luis Ferreira Nascimento; Victor Souza Sgarbi | D26: Maceió | F26: Registro concedido | G26: 2023 | H26: BR 51 2023 001019 7 | I26: N/A
A27: 9 | B27: PG Analytics - Observatório do Sistema Nacional de Pós-Graduação | C27: Carlos Henrique Almeida Alves; Cleber Nauber Dos Santos; Marcelo Embiruçu De Souza; Marcio Luis Ferreira Nascimento; Victor Souza Sgarbi | D27: Maceió | F27: Registro concedido | G27: 2023 | H27: BR 51 2023 002411 2 | I27: 23041.026532/2023-91
A28: 10 | B28: Processo de difusão de epidemias em uma dimensão - simulação estacionaria | C28: Andre Lima Moura; Caio Eduardo Pereira De Farias; Carlos Argolo Pereira Alves; Cleber Nauber Dos Santos; Iram Marcelo Gléria; Marcelo Leite Lyra; Samuel Silva Albuquerque | D28: Maceió | F28: Registro concedido | G28: 2023 | H28: BR 51 2023 002745 6 | I28: 23041.028167/2023-59
A29: 11 | B29: FERCEN - Ferramenta de Controle de Recursos Energéticos | C29: Augusto César Lúcio De Oliveira; João Pedro Nobre Mendes | D29: Arapiraca | F29: Registro concedido | G29: 2023 | H29: BR 51 2023 003437 1 | I29: 23041.040862/2023-99
A30: 12 | B30: Notifica: uma plataforma digital para controle e para monitoramento de notificações compulsórias de doenças e agravos | C30: Artur Henrique Ferreira Dos Santos Silva; Bianca Nicoly Amorim De Castro Alves; Evandro Da Silva Melo Junior; Felipe Da Silva Santos; Gabriel De Jesus Santos; Gabriel Soares Da Silva Santos; João Vitor Laranjeira Bernardino; Lousanny Caires Rocha Melo; Lucas Rodrigues Santos; Micledson Carlos Santos De Lima; Robson Alves Gominho; Samila Raphaela De Oliveira; Tarsis Marinho De Souza; Thiago De Almeida Pereira Filho; Thiago Gazaroli Cardoso; Victor Luan De Lima Lemos; Wallisson Rony De Magalhães Neves | D30: Arapiraca | F30: Registro concedido | G30: 2023 | H30: BR 51 2023 004018 5 | I30: 23041.043663/2023-32
A31: 13 | B31: Conecta: uma plataforma digital para conectar empresas e instituições científicas, tecnológicas e de inovação (ICTs) | C31: Artur Henrique Ferreira Dos Santos Silva; Augusto César Lúcio De Oliveira; Bianca Nicoly Amorim De Castro Alves; Carlos Eduardo Rocha Nunes; Eduardo Lúcio De Queiroz; Emerson Floriano Da Silva; Felipe Da Silva Santos; Gabriel De Jesus Santos; Gabriel Soares Da Silva Santos; Guilherme De Jesus Vieira; Ismael Felix Da Rocha; José Mateus Rian Das Chagas; João Vitor Laranjeira Bernardino; Lessa Apolinario Da Silva Neto; Lucas Rodrigues Santos; Micledson Carlos Santos De Lima; Renato Alves Timoteo Muniz; Tarsis Marinho De Souza; Thiago Gazaroli Cardoso; Wallisson Rony De Magalhães Neves | D31: Arapiraca | F31: Registro concedido | G31: 2023 | H31: BR 51 2023 004019 3 | I31: 23041.044362/2023-26
A32: Registros de desenho industrial
A33: Nº | B33: Projeto | C33: Orientador | D33: Campus | E33: E-mail | F33: Status | G33: Ano de concessão | H33: Processo INPI | I33: Processo no Sipac
A34: 1
A35: 2
A36: 3
A37: 4
A38: 5
A39: 6
A40: 7
...

Sheet 2022
A1: Solicitações — 2022
A2: Pedidos de Patentes
A3: Nº | B3: Projeto | C3: Orientador | D3: Campus | E3: E-mail | F3: Status | G3: Ano de concessão | H3: Processo INPI | I3: Processo no Sipac
A4: 1 | B4: Sistema Integrado de Hardware e Software Aplicado à Manutenção Corretiva e Preventiva de Equipamentos Industriais | C4: Alex Aguiar da Silva; Fabrício Caymon Nogueira | D4: Coruripe | E4: alex.aguiar@ifal.edu.br | F4: Acompanhamento na revista | G4: 2022 | H4: BR 10 2022 023606 2 | I4: 23041.043075/2022-18
A5: 2 | B5: Aproveitamento De Cascalho De Perfuração De Poços De Petróleo Na Produção De Concreto Permeável | C5: José Diôgo Barbosa De Almeida; Sheyla Karolina Justino Marque; Áurea Luiza Quixabeira Rosa E Silva Rapôso | D5: Coruripe | E5: sheyla.marques@ifal.edu.br | F5: Acompanhamento na revista | G5: 2022 | H5: BR 10 2022 008186 7 | I5: 23041.010927/2022-91
A6: 3 | B6: Produção de Filmes de Revestimento Alimentício à Base do Coproduto da Extração da Própolis Vermelha | C6: Morgana Carine Santos De Lima; André Suêldo Tavares De Lima; Ticiano Gomes Do Nascimento; Johnnatan Duarte De Freitas; Isabel Cristina Celerino De Moraes Porto; Jeniffer Mclaine Duarte De Freitas; Tatiane Luciano Balliano; Demetrius Pereira Morilla; Alan John Duarte De Freitas | D6: Maceió | E6: johnnatan.duarte@ifal.edu.br | F6: Acompanhamento na revista | G6: 2022 | H6: BR 10 2022 005680 3 | I6: 23041.007350/2022-30
A7: 4 | B7: Microcápsula Contendo Extrato De Própolis Marrom, Processo De Obtenção E Uso Da Mesma. | C7: Irinaldo Diniz Basílio Júnior; Alan John Duarte De Freitas; Valdemir Da Costa Silva; Arthur Luy Tavares Ferreira Borges; Jennifer Mclaine Duarte De Freitas; Fernanda Geny Calheiros Silva; Mailde Jéssica Liodorio Dos Santos; Clara Andrezza Crisóstomo Bezerra Costa; Orlando Franscico Da Silva Moura; Johnnatan Duarte Freitas; Demetrius Pereira Morilla; Lucas Rafael De Oliveira Silva; Monique Almeida Vila Nova; Luis Carlos Ferreira De Oliveira; Ticiano Gomes Do Nascimento; Fabiane Caxico De Abreu Galdino; Emanoel Guilhermino Da Silva Júnior; Abel Barbosa Lira Neto; João Victor Lessa De Oliveira; Thaíse Da Silva Santos; Jhonatan David Santos Das Neves; Jailson Ferreira De Freitas; Rubens Pessoa De Barros; Jean Ferreira De Freitas; Sidney José Dos Santos; Celso Silva Caldas | D7: Maceió | E7: jhonatan.david@uneal.edu.br | F7: Acompanhamento na revista | G7: 2022 | H7: BR 10 2022 002341 7 | I7: 23041.038302/2021-11
A8: 5 | B8: Argamassa De Assentamento Com Substituição Parcial Do Agregado Miúdo Por Embalagens Cartonadas Trituradas | C8: Ronny Francisco Marques De Souza; Sheyla Karolina Justino Marques; Juliana Lira Brito | D8: Piranhas | E8: sheyla.marques@ifal.edu.br | F8: Acompanhamento na revista | G8: 2022 | H8: BR 10 2022 013616-5 | I8: 23041.028961/2022-11
A9: 6 | B9: Caracterização E Valorização Da Farinha De Resíduo De Malte Como Ingrediente Para fabricação De Produtos De Panificação. | C9: Jennifer Mclaine Duarte De Freitas; Clara Andrezza Crisóstomo Bezerra Costa; Johnnatan Duarte Freitas; Victor Cordeiro Fireman; Layanne Cabral De Almeida; Alan John Duarte Freitas; Ingrid Sofia Vieira De Melo; Jório Bezerra Cabral Júnior; André Suêldo Tavares De Lima; Ticiano Gomes Do Nascimento | D9: Maceió | E9: jorio.cabral@igdema.ufal.br | F9: Acompanhamento na revista | G9: 2022 | H9: BR 10 2022 012297 0 | I9: 23041.028738/2022-74
A10: 7 | B10: Elaboração de um produto tipo catchup de beterraba | C10: Emanuel Neto Alves De Oliveira; Danielle Martins Lemos; Elisabete Piancó De Sousa | D10: Batalha | E10: danieleali@gmail.com | F10: Acompanhamento na revista | G10: 2022 | H10: BR 10 2022 003394 3 | I10: 23041.027187/2020-60
A11: 8
A12: 9
A13: 10
A14: 11
A15: 12
A16: Registros de programa de computador
A17: Nº | B17: Projeto | C17: Orientador | D17: Campus | E17: E-mail | F17: Status | G17: Ano de concessão | H17: Processo INPI | I17: Processo no Sipac
A18: 1 | B18: QUALYTEAM VACCINE | C18: Emesson Michael Pereira Gois; Jarlisson José De Lira; Paulo Cesar Do Nascimento Cunha; Wellighton José Serapião | D18: Arapiraca | F18: Acompanhamento na revista | G18: 2022 | H18: BR 51 2022 002671 6 | I18: 23041.034328/2022-62
A19: 2 | B19: Inventário Certo | C19: Ednildo Macena Da Silva Filho; Nícolas Lopes De Menezes; Paula Pradines De Albuquerque Lôbo; Rodrigo Fernandes Vanderlei Vasco | D19: Benedito Bentes | F19: Acompanhamento na revista | G19: 2022 | H19: BR 51 2022 002416 0 | I19: 23041.036240/2022-85
A20: 3 | B20: BIOFORCA | C20: Ebenézer Bernardes Correia Silva; Maria Luzenita Wagner Mallmann; Márcio Cavalcante Vila Nova; Nathan Rafael Mendonça De Assis. | D20: Maceió | F20: Acompanhamento na revista | G20: 2022 | H20: BR 51 2022 003161 2 | I20: 23041.037717/2022-40
A21: 4 | B21: CHATBOT MARVIN | C21: Cledja Karina Rolim Da Silva; Jonas Sousa Leandro; Matheus Breno Dos Santos Moura | D21: Arapiraca | F21: Acompanhamento na revista | G21: 2022 | H21: BR 51 2022 003591 0 | I21: 23041.052406/2022-19
A22: 5 | B22: BIODINGO | C22: Cícero Jacinto Da Silva Neto, Ebenézer Fernandes Correia Silva; Eike Fabricio Da Silva, Maria Luzenita Wagner Mallmann; Ruan Tenório De Melo | D22: Arapiraca | F22: Acompanhamento na revista | G22: 2022 | H22: BR 51 2022 003600 2 | I22: 23041.052530/2022-76
A23: 6 | B23: SementeSuite | C23: Cosmo Rufino De Lima; Fábio José Marques; Humberto Beltrão Da Cunha Júnior; José Carlos Almeida Patrício Júnior; Márcio Fléquisson Alves Miranda; Pablo Radamés Cabral De França; Érik Alves Almeida | D23: Arapiraca | E23: fabio.marques@ifal.edu.br | F23: Acompanhamento na revista | G23: 2022 | H23: BR 51 2022 002731 3 | I23: N/A
A24: 7 | B24: Processamento De Linguagem Natural Para Frase Por Ditado | C24: Diego Dermeval Medeiros Da Cunha Matos; Gabriel Augusto Barbosa; Hilário Tomaz Alves De Oliveira; Hyan Hugo Noá Batista; Ig Ibert Bittencourt Santana Pinto; Jário José Dos Santos Júnior; Mauricio Ronny De Almeida Souza; Nicolas Yan Bittencourt Santana Pereira; Péricles Barbosa Cunha De Miranda; Rafael Ferreira Leite De Mello; Rodrigo Ludermir De Oliveira; Seiji Isotani; Thiago Damasceno Cordeiro; Tiago Barbosa De Lima | D24: Marechal Deodoro | F24: Acompanhamento na revista | G24: 2022 | H24: BR 51 2022 001752 0 | I24: Somos COTitular
A25: 8 | B25: Processamento De Linguagem Natural Para Frase Por Imagem | C25: Diego Dermeval Medeiros Da Cunha Matos; Gabriel Augusto Barbosa; Hilário Tomaz Alves De Oliveira; Hyan Hugo Noá Batista; Ig Ibert Bittencourt Santana Pinto; Jário José Dos Santos Júnior; Mauricio Ronny De Almeida Souza; Nicolas Yan Bittencourt Santana Pereira; Péricles Barbosa Cunha De Miranda; Rafael Ferreira Leite De Mello; Rodrigo Ludermir De Oliveira; Seiji Isotani; Thiago Damasceno Cordeiro; Tiago Barbosa De Lima | D25: Marechal Deodoro | F25: Acompanhamento na revista | G25: 2022 | H25: BR 51 2022 001753 9 | I25: Somos COTitular
A26: 9 | B26: Processamento De Linguagem Natural Para Palavra Por Ditado | C26: Diego Dermeval Medeiros Da Cunha Matos; Gabriel Augusto Barbosa; Hilário Tomaz Alves De Oliveira; Hyan Hugo Noá Batista; Ig Ibert Bittencourt Santana Pinto; Jário José Dos Santos Júnior; Mauricio Ronny De Almeida Souza; Nicolas Yan Bittencourt Santana Pereira; Péricles Barbosa Cunha De Miranda; Rafael Ferreira Leite De Mello; Rodrigo Ludermir De Oliveira; Seiji Isotani; Thiago Damasceno Cordeiro; Tiago Barbosa De Lima | D26: Marechal Deodoro | F26: Acompanhamento na revista | G26: 2022 | H26: BR 51 2022 001754 7 | I26: Somos COTitular
A27: 10 | B27: Processamento De Linguagem Natural Para Redação Coesão | C27: Diego Dermeval Medeiros Da Cunha Matos; Gabriel Augusto Barbosa; Hilário Tomaz Alves De Oliveira; Hyan Hugo Noá Batista; Ig Ibert Bittencourt Santana Pinto; Jário José Dos Santos Júnior; Mauricio Ronny De Almeida Souza; Nicolas Yan Bittencourt Santana Pereira; Péricles Barbosa Cunha De Miranda; Rafael Ferreira Leite De Mello; Rodrigo Ludermir De Oliveira; Seiji Isotani; Thiago Damasceno Cordeiro; Tiago Barbosa De Lima | D27: Marechal Deodoro | F27: Acompanhamento na revista | G27: 2022 | H27: BR 51 2022 001772 5 | I27: Somos COTitular
A28: 11 | B28: Processamento De Linguagem Natural Para Redação Coesão | C28: Diego Dermeval Medeiros Da Cunha Matos; Gabriel Augusto Barbosa; Hilário Tomaz Alves De Oliveira; Hyan Hugo Noá Batista; Ig Ibert Bittencourt Santana Pinto; Jário José Dos Santos Júnior; Mauricio Ronny De Almeida Souza; Nicolas Yan Bittencourt Santana Pereira; Péricles Barbosa Cunha De Miranda; Rafael Ferreira Leite De Mello; Rodrigo Ludermir De Oliveira; Seiji Isotani; Thiago Damasceno Cordeiro; Tiago Barbosa De Lima | D28: Marechal Deodoro | F28: Acompanhamento na revista | G28: 2022 | H28: BR 51 2022 001758 0 | I28: Somos COTitular
A29: 12 | B29: Processamento De Linguagem Natural Para Redação Ortografia | C29: Diego Dermeval Medeiros Da Cunha Matos; Gabriel Augusto Barbosa; Hilário Tomaz Alves De Oliveira; Hyan Hugo Noá Batista; Ig Ibert Bittencourt Santana Pinto; Jário José Dos Santos Júnior; Mauricio Ronny De Almeida Souza; Nicolas Yan Bittencourt Santana Pereira; Péricles Barbosa Cunha De Miranda; Rafael Ferreira Leite De Mello; Rodrigo Ludermir De Oliveira; Seiji Isotani; Thiago Damasceno Cordeiro; Tiago Barbosa De Lima | D29: Marechal Deodoro | F29: Acompanhamento na revista | G29: 2022 | H29: BR 51 2022 001770 9 | I29: Somos COTitular
A30: 13 | B30: Processamento De Linguagem Natural Para Redação Pontuação | C30: Diego Dermeval Medeiros Da Cunha Matos; Gabriel Augusto Barbosa; Hilário Tomaz Alves De Oliveira; Hyan Hugo Noá Batista; Ig Ibert Bittencourt Santana Pinto; Jário José Dos Santos Júnior; Mauricio Ronny De Almeida Souza; Nicolas Yan Bittencourt Santana Pereira; Péricles Barbosa Cunha De Miranda; Rafael Ferreira Leite De Mello; Rodrigo Ludermir De Oliveira; Seiji Isotani; Thiago Damasceno Cordeiro; Tiago Barbosa De Lima | D30: Marechal Deodoro | F30: Acompanhamento na revista | G30: 2022 | H30: BR 51 2022 001771 7 | I30: Somos COTitular
A31: 14 | B31: Processamento De Linguagem Natural Para Redação Viabilidade Cópia | C31: Diego Dermeval Medeiros Da Cunha Matos; Gabriel Augusto Barbosa; Hilário Tomaz Alves De Oliveira; Hyan Hugo Noá Batista; Ig Ibert Bittencourt Santana Pinto; Jário José Dos Santos Júnior; Mauricio Ronny De Almeida Souza; Nicolas Yan Bittencourt Santana Pereira; Péricles Barbosa Cunha De Miranda; Rafael Ferreira Leite De Mello; Rodrigo Ludermir De Oliveira ; Seiji Isotani; Thiago Damasceno Cordeiro; Tiago Barbosa De Lima | D31: Marechal Deodoro | F31: Acompanhamento na revista | G31: 2022 | H31: BR 51 2022 001774 1 | I31: Somos COTitular
A32: 15 | B32: RELAXING | C32: Almira Alves Dos Santos; Flávio Mota Medeiros; Isabella Costa Figueiredo Medeiros; Yuri David Queiroz Assunção De Azevedo | D32: Reitoria | F32: Acompanhamento na revista | G32: 2022 | H32: BR 51 2020 001677 4 | I32: 23041.014585/2020-16
A33: 16 | B33: E-NOLOGY | C33: Jackson Silva Bezerra; José Anderson Delmondes Caitano; Marici Lopes Da Silva; Priscylla Maria Da Silva Sousa | D33: Rio Largo | F33: Acompanhamento na revista | G33: 2022 | H33: BR 51 2022 000515 8 | I33: 23041.006249/2022-61
A34: 17 | B34: Jogo De Linguagens | C34: Ana Luiza Azevedo Fireman; João Pedro Santana Santos; Lucas Akira Tanabe Quaresma; Luiz Felipe Naziazeno Neto | D34: Piranhas | F34: Acompanhamento na revista | G34: 2022 | H34: BR 51 2022 001686 9 | I34: 23041.024473/2022-35
A35: 18 | B35: Programa De Gestão E Desempenho | C35: Antônio Cavalcanti Cajueiro Neto; Fernando Antônio Corado Carneiro; Iran Rodrigues Gonzaga Júnior; Marcos Paulo José De Melo Silva | D35: Reitoria | F35: Acompanhamento na revista | G35: 2022 | H35: BR 51 2022 001570 6 | I35: 23041.025586/2022-58
A36: Registros de desenho industrial
A37: Nº | B37: Projeto | C37: Orientador | D37: Campus | E37: E-mail | F37: Status | G37: Ano de concessão | H37: Processo INPI | I37: Processo no Sipac
A38: 1
A39: 2
A40: 3
...

Sheet 2021
A1: Solicitações — 2021
A2: Pedidos de Patentes
A3: Nº | B3: Projeto | C3: Orientador | D3: Campus | E3: E-mail | F3: Status | G3: Ano de concessão | H3: Processo INPI | I3: Processo no Sipac
A4: 1 | B4: Desenvolvimento de argamassa de assentamento e revestimento com conchas de sururu | C4: Renato Carvalho Menezes | D4: Marechal Deodoro | E4: renato.menezes@ifal.edu.br | F4: Acompanhamento na revista | G4: 2021 | H4: BR 10 2021 021385 0 | I4: 23041.007875/2021-94
A5: 2 | B5: Produção de bloco intertravado de concreto autoadensável com adição de finos de resíduo cerâmico provenientes da Construção Civil | C5: Ronny Francisco | D5: Marechal Deodoro | E5: ronny.souza@ifal.edu.br | F5: Acompanhamento na revista | G5: 2021 | H5: BR 10 2021 024396 1 | I5: 23041.037578/2021-73
A6: 3 | B6: Canudo biodegradavel a partir de cera de abelha | C6: Danielle Lemos | D6: Batalha | E6: danielle.lemos@ifal.edu.br | F6: Acompanhamento na revista | G6: 2021 | H6: BR 10 2021 017563 0 | I6: 23041.047288/2019-13
A7: 4 | B7: Processamento de brownie a partir da obtenção da farinha de inhame por secagem convectiva | C7: Neide Aparecida Ferreira Machado | D7: Murici | E7: neide.ferreira@ifal.edu.br | F7: Acompanhamento na revista | G7: 2021 | H7: BR 10 2021 014926 4 | I7: 23041.025879/2020-73 || 23041.033695/2024-19
A8: 5 | B8: Composição De Microcápsulas De Uncaria Tomentosa, Processos De Obtenção E Caracterização De Microcápsulas De Uncaria Tomentosa E Usos Da Mesma | C8: Alan John Duarte De Freitas | D8: Maceió | E8: alan.freitas@ifal.edu.br | F8: Acompanhamento na revista | G8: 2021 | H8: BR 10 2021 022111 9 | I8: 23041.044244/2025-80 | J8: SomosCOTitular
A9: 6 | B9: Produção de Pimenta Vermelha Tipo "Biquinho" (Capsicum Chinense Jacq.) Em Pó | C9: Alexandre José De Melo Queiroz; Rossana Maria Feitosa De Figueredo; Rodrigo Leite Moura; Pedro Francisco Do Rego Júnior | D9: Piranhas | E9: rodrigo.moura@ifal.edu.br | F9: Acompanhamento na revista | G9: 2021 | H9: BR 10 2021 014391 6 | I9: 23041.029624/2025-94 | J9: SomosCOTitular
A10: 7
A11: 8
A12: 9
A13: 10
A14: Registros de programa de computador
A15: Nº | B15: Projeto | C15: Orientador | D15: Campus | E15: E-mail | F15: Status | G15: Ano de concessão | H15: Processo INPI | I15: Processo no Sipac
B16: Plataforma para monitoramento pacientes com suspeitas ou confirmados de COVID-19 | D16: Arapiraca | E16: tarsis.souza@ifal.edu.br | F16: Registro concedido | G16: 2021 | H16: BR 51 2021 000791 3 | I16: 23041.027490/2020-62
A17: 2 | B17: My Moto | C17: Antônio Alexandre De Andrade Júnior; Luiz Roberto Torres Dos Santos; Ollin Magno Santos; Priscylla Maria Da Silva Sousa | D17: Rio Largo | E17: priscylla.sousa@ifal.edu.br | F17: Registro concedido | G17: 2021 | H17: BR 51 2021 000801 4 | I17: 23041.036269/2020-03
A18: 3 | B18: TERAMUSIC | C18: Fernando Antônio Guimarães Tenório; Jussara Ramos Da Silva; Lucas Rodrigues Santos; Wallisson Rony De Magalhães Neves | D18: Arapiraca | E18: lrs20@aluno.ifal.edu.br | F18: Registro concedido | G18: 2021 | H18: BR 51 2021 000802 2 | I18: 23041.028672/2020-51
A19: 4 | B19: Sisvac – Sistema De Agendamento de Vacinas | C19: Evandro Da Silva Melo Junior; Gabriel Soares Da Silva Santos; Lousanny Caires Rocha Melo; Matheus Breno Dos Santos Moura; Tarsis Marinho De Souza; Vinnicyus Philyppe Gracindo Alves Leite; Wallisson Rony De Magalhães Neves | D19: Arapiraca | E19: tarsis.souza@ifal.edu.br | F19: Registro concedido | G19: 2021 | H19: BR 51 2021 001471 5 | I19: 23041.017736/2021-79
A20: 5 | B20: Sistema De Recomendação De Adubação E Calagem De Culturas Agrícolas | C20: Enio Gomes Flor Souza; Lucas Akira Tanabe Quaresma; Luiz Felipe Naizazeno Neto | D20: Palmeira dos Índios | E20: luiz.felipe@ifal.edu.br | F20: Registro concedido | G20: 2021 | H20: BR 51 2021 001604 1 | I20: 23041.018528/2021-97
A21: 6 | B21: GESTEMPO | C21: Rossana Viana Gaia; Valmir Rogério E Silva | D21: Maceió | E21: rossana.gaia@ifal.edu.br | F21: Registro concedido | G21: 2021 | H21: BR 51 2021 001715 3 | I21: 23041.018610/2021-11
A22: 7 | B22: SMART SYSTEM | C22: Eduardo Frigoletto De Menezes; Iran Rodrigues Gonzaga Júnior; Marcos Paulo José De Melo Silva | D22: Reitoria | E22: eduardo.frigoletto@ifal.edu.br | F22: Registro concedido | G22: 2021 | H22: BR 51 2021 001605 0 | I22: 23041.019289/2021-92
A23: 8 | B23: INFO PANC | C23: André Suêldo Tavares De Lima; Felipe Augusto Oliveira Lopes; Tadeu Patelo Barbosa | D23: Reitoria | E23: andre.sueldo@ifal.edu.br | F23: Registro concedido | G23: 2021 | H23: BR 51 2021 003050 8 | I23: 23041.024588/2021-49
A24: 9 | B24: CALC-COMPOSITE | C24: José Antônio França De Araújo; Raul Bernardo Pontes Pires | D24: Maceió | F24: Registro concedido | G24: 2021 | H24: BR 51 2021 002747 7 | I24: 23041.034172/2021-39
A25: 10 | B25: SementeSuite: Aplicativo para otimizar análise de sementes | C25: Cosmo Rufino De Lima; Fábio José Marques; Humberto Beltrão Da Cunha Júnior; José Carlos Almeida Patrício Júnior; Márcio Fléquisson Alves Miranda; Pablo Radamés Cabral De França; Érik Alves Almeida | D25: Piranhas | E25: fabio.marques@ifal.edu.br | F25: Registro concedido | G25: 2021 | H25: BR 51 2021 002696 9 | I25: N/A
A26: 11 | B26: E-lixo | C26: Adriana dos Santos Franco | D26: Maceió | E26: adriana.franco@ifal.edu.br | F26: Registro concedido | G26: 2021 | H26: BR 51 2021 000267 9 | I26: Somos COTitular
A27: 12 | B27: ERGOBIO | C27: Aydano Pamponet Machado; Evandro De Barros Costa; Leandro Dias Da Silva; Leonardo Melo De Medeiros; Luís Felipe Vieira Silva; Maria Júlia De Oliveira Vieira; Thayse Justino Montenegro Falcão | D27: Maceió | E27: lmm2@aluno.ifal.edu.br | F27: Registro concedido | G27: 2021 | H27: BR 51 2021 000205 9 | I27: N/A
A28: 13
A29: Registros de desenho industrial
A30: Nº | B30: Projeto | C30: Orientador | D30: Campus | E30: E-mail | F30: Status | G30: Ano de concessão | H30: Processo INPI | I30: Processo no Sipac
A31: 1
A32: 2
A33: 3
A34: 4
A35: 5
A36: 6
A37: 7
A38: 8
A39: 9
A40: 10
...

Sheet 2020
A1: Solicitações — 2020
A2: Pedidos de Patentes
A3: Nº | B3: Projeto | C3: Orientador | D3: Campus | E3: E-mail | F3: Status | G3: Ano de concessão | H3: Processo INPI | I3: Processo no Sipac
A4: 1 | B4: Tijolo Ecológico Produzido A Partir Da Combinação De Cimento, Solo Laterítico E Carago | C4: Priscylla Cinthya Alves Gondim; Wilson Acchar; Sheyla Karolina Justino Marques; João De Medeiros Dantas Neto | D4: Marechal Deodoro | E4: sheyla.marques@ifal.edu.br | F4: Acompanhamento na revista | G4: 2020 | H4: BR 10 2020 018396 6 | I4: 23041.036713/2025-97 | J4: SomosCOTitular
A5: 2
A6: 3
A7: 4
A8: 5
A9: 6
A10: 7
A11: 8
A12: 9
A13: 10
A14: 11
A15: 12
A16: 13
A17: Registros de programa de computador
A18: Nº | B18: Projeto | C18: Orientador | D18: Campus | E18: E-mail | F18: Status | G18: Ano de concessão | H18: Processo INPI | I18: Processo no Sipac
A19: 1 | B19: FundPro | C19: Thiago Delfino Lima Vasconcelos | D19: Palmeira dos Índios | E19: thiago.vasconcelos@ifa | F19: Registro concedido | G19: 2020 | H19: BR 51 2020 002983 3 | I19: 23041.030013/2020-84
A20: 2 | B20: LABREAL | C20: Dalton Serafim De Oliveira; Elisangela Costa Santos; Ermesson Lima Dos Santos | D20: Penedo | E20: elisangela.santos@ifal.edu.br | F20: Registro concedido | G20: 2020 | H20: BR 51 2020 000005 3 | I20: N/A
A21: 3 | B21: VRLAB | C21: Dalton Serafim De Oliveira; Elisangela Costa Santos; Ermesson Lima Dos Santos | D21: Penedo | E21: elisangela.santos@ifal.edu.br | F21: Registro concedido | G21: 2020 | H21: BR 51 2020 000010 0 | I21: N/A
A22: 4 | B22: QUIZ QUÍMICA | C22: Dalton Serafim De Oliveira; Elisangela Costa Santos; Ermesson Lima Dos Santos | D22: Penedo | E22: elisangela.santos@ifal.edu.br | F22: Registro concedido | G22: 2020 | H22: BR 51 2020 000011 8 | I22: N/A
A23: 5 | B23: QIWEB | C23: Handrik Palmeira Magalhães; João Paulo Ajala Sorgato | D23: Reitoria | E23: handrik@ifal.edu.br | F23: Registro concedido | G23: 2020 | H23: BR 51 2020 000335 4 | I23: N/A
A24: 6 | B24: ACESSBUS | C24: Ana Karla Cavalcante Ferreira; Everton Macena De Paiva; Mateus Guedes De Lima | D24: Reitoria | E24: karla.cavalcante@ifal.e | F24: Registro concedido | G24: 2020 | H24: BR 51 2020 000336 2 | I24: N/A
A25: 7 | B25: ALGORIF | C25: Flávio Mota Medeiros | D25: Maceió | E25: flavio.medeiros@ifal.edu.br | F25: Registro concedido | G25: 2020 | H25: BR 51 2020 002984 1 | I25: N/A
A26: 8 | B26: RELAXING | C26: Almira Alves Dos Santos; Flávio Mota Medeiros; Isabella Costa Figueiredo Medeiros; Yuri David Queiroz Assunção De Azevedo | D26: Reitoria | E26: flavio.medeiros@ifal.edu.br | F26: Registro concedido | G26: 2020 | H26: BR 51 2020 001677 4 | I26: 23041.014585/2020-16
A27: 9
A28: 10
A29: 11
A30: 12
A31: 13
A32: Registros de desenho industrial
A33: Nº | B33: Projeto | C33: Orientador | D33: Campus | E33: E-mail | F33: Status | G33: Ano de concessão | H33: Processo INPI | I33: Processo no Sipac
A34: 1
A35: 2
A36: 3
A37: 4
A38: 5
A39: 6
A40: 7
...

Sheet 2019
A1: Solicitações — 2019
A2: Pedidos de Patentes
A3: Nº | B3: Projeto | C3: Orientador | D3: Campus | E3: E-mail | F3: Status | G3: Ano de concessão | H3: Processo INPI | I3: Processo no Sipac
